<?xml version="1.0"?>
<robot name="wpb_home_gazebo">

<link name="base_footprint">
  <visual>
    <origin xyz="0 0 0" rpy="0 0 0" />
    <geometry>
      <box size="0.05 0.05 0.001" />
    </geometry>
  </visual>
</link>

<joint name="base_joint" type="fixed">
  <origin xyz="0 0 0" rpy="0 0 0" />
  <parent link="base_footprint"/>
  <child link="base_link" />
</joint>

<!-- base -->
<link name="base_link">
  <visual>
   <geometry>
    <box size="0.01 0.01 0.001" />
   </geometry>
   <origin rpy = "0 0 0" xyz = "0 0 0"/>
  </visual>
</link>

<!-- body -->
<link name = "body_link">
  <visual>
    <geometry>
      <mesh filename="package://wpr_simulation2/meshes/wpb_home/wpb_home_mani.dae" scale="1 1 1"/>
    </geometry>
    <origin rpy = "1.57 0 1.57" xyz = "-.225 -0.225 0"/>
  </visual>
  <collision>
    <origin xyz="0.001 0 .065" rpy="0 0 0" />
    <geometry>
      <cylinder length="0.13" radius="0.226"/>
    </geometry>
  </collision>
  <inertial>
    <mass value="25"/>
    <inertia ixx="4.00538" ixy="0.0" ixz="0.0" iyy="4.00538" iyz="0.0" izz="0.51076"/>
  </inertial>
</link>
<joint name = "base_to_body" type = "fixed">
  <parent link = "base_link"/>
  <child link = "body_link"/>
  <origin rpy="0 0 0" xyz="0 0 0"/> <!--pos-->
</joint>
<!-- top of base -->
<link name = "base_top_link">
  <collision>
    <origin xyz="0 0 0" rpy="0 0 0" />
    <geometry>
      <box size="0.33 0.31 0.03"/>
    </geometry>
  </collision>
  <inertial>
    <mass value="0.01"/>
    <inertia ixx="0.01" ixy="0.0" ixz="0.0" iyy="0.01" iyz="0.0" izz="0.01"/>
  </inertial>
</link>
<joint name = "body_to_top" type = "fixed">
  <parent link = "body_link"/>
  <child link = "base_top_link"/>
  <origin rpy="0 0 0" xyz="0.01 0 0.2"/> <!--pos-->
</joint>
<!-- back -->
<link name = "body_back_link">
  <collision>
    <origin xyz="0 0 0" rpy="0 0 0" />
    <geometry>
      <box size="0.03 0.23 1.05"/>
    </geometry>
  </collision>
  <inertial>
    <mass value="0.01"/>
    <inertia ixx="0.01" ixy="0.0" ixz="0.0" iyy="0.01" iyz="0.0" izz="0.01"/>
  </inertial>
</link>
<joint name = "body_to_back" type = "fixed">
  <parent link = "base_top_link"/>
  <child link = "body_back_link"/>
  <origin rpy="0 0.31 0" xyz="-0.038 0 0.5"/> 
</joint>
<!-- head -->
<link name = "head_link">
  <collision>
    <origin xyz="0 0 0" rpy="0 0 0" />
    <geometry>
      <box size="0.07 0.28  0.06"/>
    </geometry>
  </collision>
  <inertial>
    <mass value="0.01"/>
    <inertia ixx="0.01" ixy="0.0" ixz="0.0" iyy="0.01" iyz="0.0" izz="0.01"/>
  </inertial>
</link>
<joint name = "body_to_head" type = "fixed">
  <parent link = "base_top_link"/>
  <child link = "head_link"/>
  <origin rpy="0 0.27 0" xyz="0.155 0 1.17"/>
</joint>
<!-- front -->
<link name = "front_link">
  <collision>
    <origin xyz="0 0 0" rpy="0 0 0" />
    <geometry>
     <box size="0.05 0.05  0.77"/>
    </geometry>
  </collision>
  <inertial>
    <mass value="2.8"/>
    <inertia ixx="0.441687775" ixy="0.0" ixz="0.0" iyy="0.0017366" iyz="0.0" izz="0.441070275"/>
  </inertial>
</link>
<joint name = "body_to_front" type = "fixed">
  <parent link = "base_top_link"/>
  <child link = "front_link"/>
  <origin rpy="0 0 0" xyz="0.1 0 0.41"/>
</joint>
<!--front_holder -->
<link name = "front_holder_link">
  <collision>
    <origin xyz="0 0 0" rpy="1.57 0 0" />
    <geometry>
     <cylinder length="0.1" radius="0.01"/>
    </geometry>
  </collision>
  <inertial>
    <mass value="0.01"/>
    <inertia ixx="0.01" ixy="0.0" ixz="0.0" iyy="0.01" iyz="0.0" izz="0.01"/>
  </inertial>
</link>
<joint name = "body_to_front_holder" type = "fixed">
  <parent link = "base_top_link"/>
  <child link = "front_holder_link"/>
  <origin rpy="0 0 0" xyz="0.215 0 0.3"/> 
</joint>

<!-- manipulator -->
<link name = "mani_lift">
  <visual>
   <geometry>
    <box size=".03 .04 .06"/>
   </geometry>
   <origin rpy = "0 0 0" xyz = "0 0 -0.06"/>
  </visual>
  <inertial>
      <mass value="1"/>
      <inertia ixx="0.000375" ixy="0.0" ixz="0.0" iyy="0.000208333" iyz="0.0" izz="0.000433333"/>
  </inertial>
</link>
<joint name="mani_base" type="prismatic">
    <parent link="base_link"/>
    <child link="mani_lift"/>
    <origin xyz="0.1 0 0.4" rpy="0 -1.5707963 0"/>
    <limit effort="1000.0" lower="0" upper="0.7" velocity="0.5"/>
    <dynamics damping="0.1" friction="0.0"/>
</joint>

<link name = "mani_elbow">
  <inertial>
       <mass value="0.1"/>
      <inertia ixx="0.0000375" ixy="0.0" ixz="0.0" iyy="0.0000208333" iyz="0.0" izz="0.0000433333"/> 
  </inertial>
</link>
<joint name="lift_elbow" type="fixed">
    <origin rpy="0 0 0" xyz="0 0 -0.08"  /> 
    <parent link="mani_lift" />
    <child link="mani_elbow" />
</joint>

<link name = "mani_forearm">
  <visual>
    <geometry>
      <mesh filename="package://wpr_simulation2/meshes/wpb_home/forearm.dae" scale=" 1 1 1 "/>
    </geometry>
    <origin rpy = "-1.5707963 3.1415926 0" xyz = "0.365 -0.037 -0.0355"/>
  </visual>
  <collision>
      <origin xyz="0.19 0 -0.01" rpy="0 0 0"/>
      <geometry>
        <box size="0.35 0.05  0.03"/>
    </geometry>
  </collision>
   <inertial>
      <mass value="0.95"/>
      <inertia ixx="0.121862813" ixy="0.0" ixz="0.0" iyy="0.0" iyz="0.0" izz="0.121862813"/> 
  </inertial>
</link>
<joint name="elbow_forearm" type="revolute">
    <axis xyz="0 1 0"/>
    <limit effort="1000.0" lower="0" upper="1.57" velocity="0.5"/>
    <origin xyz="0 0 0" rpy="0 0 0" />
    <dynamics damping="0.1" friction="0.0"/>
    <parent link="mani_elbow" />
    <child link="mani_forearm" />
</joint>

<!-- left finger -->
  <link name = "mani_left_finger">
    <visual>
        <geometry>
            <box size="0.1 0.01  0.037"/>
        </geometry>
        <origin rpy = "0 0 0" xyz = "0.05 0 0"/>
    </visual>
    <collision>
      <origin xyz="0.076 0 0" rpy="0 0 0"/>
      <geometry>
        <box size="0.02 0.01  0.037"/>
      </geometry>
    </collision>
    <inertial>
      <mass value="0.1"/>
      <inertia ixx="0.001" ixy="0.0" ixz="0.001" iyy="0.0" iyz="0.0" izz="0.001"/>
    </inertial>
  </link>
  <gazebo reference="mani_left_finger">
    <material>Gazebo/Grey</material>
    <kp>1000000.0</kp>
    <kd>100.0</kd>
    <mu1>30.0</mu1>
    <mu2>30.0</mu2>
    <maxVel>1.0</maxVel>
    <minDepth>0.001</minDepth>
  </gazebo>
  <joint name = "palm_left_finger" type = "revolute">
    <parent link = "mani_forearm"/>
    <child link = "mani_left_finger"/>
    <origin xyz = "0.33 0.0125 -0.006"/>
    <axis xyz = "0 0 1"/>
    <limit effort = "1000.0" lower="-0.07" upper="1.57" velocity="0.5"/>
    <dynamics damping="0.1" friction="0.0"/>
  </joint>

  <!-- left fingertip -->
   <link name = "mani_left_finger_tip">
    <visual>
        <geometry>
            <box size="0.07 0.006  0.025"/>
        </geometry>
        <origin rpy = "0 0 0" xyz = "0.035 0 0"/>
    </visual>
    <collision>
      <origin xyz="0.035 0 0" rpy="0 0 0"/>
      <geometry>
        <box size="0.07 0.006  0.025"/>
      </geometry>
    </collision>
    <collision>
    <origin xyz="0.071 -0.005 0" rpy="0 0 0" />
    <geometry>
      <box size="0.001 0.008  0.025"/>
    </geometry>
  </collision>
    <inertial>
      <mass value="0.1"/>
      <inertia ixx="0.001" ixy="0.0" ixz="0.001" iyy="0.0" iyz="0.0" izz="0.001"/>
    </inertial>
  </link>
  <gazebo reference="mani_left_finger_tip">
    <material>Gazebo/Grey</material>
    <kp>1000000.0</kp>
    <kd>100.0</kd>
    <mu1>30.0</mu1>
    <mu2>30.0</mu2>
    <maxVel>1.0</maxVel>
    <minDepth>0.001</minDepth>
  </gazebo>
  <joint name = "left_finger_tip" type = "revolute">
    <parent link = "mani_left_finger"/>
    <child link = "mani_left_finger_tip"/>
    <origin xyz = "0.1 0 0"/>
    <axis xyz = "0 0 1"/>
    <limit effort = "1000.0" lower="-1.57" upper="1.57"  velocity="0.5"/>
    <mimic joint = "palm_left_finger" multiplier = "-1" offset = "0"/>
    <dynamics damping="0.1" friction="0.0"/>
  </joint>

  <!-- right finger -->
  <link name = "mani_right_finger">
    <visual>
        <geometry>
            <box size="0.1 0.01  0.037"/>
        </geometry>
        <origin rpy = "0 0 0" xyz = "0.05 0 0"/>
    </visual>
    <collision>
      <origin xyz="0.076 0 0" rpy="0 0 0"/>
      <geometry>
        <box size="0.02 0.01  0.037"/>
      </geometry>
    </collision>
    <inertial>
      <mass value="0.1"/>
      <inertia ixx="0.001" ixy="0.0" ixz="0.001" iyy="0.0" iyz="0.0" izz="0.001"/>
    </inertial>
  </link>
  <gazebo reference="mani_right_finger">
    <material>Gazebo/Grey</material>
    <kp>1000000.0</kp>
    <kd>100.0</kd>
    <mu1>30.0</mu1>
    <mu2>30.0</mu2>
    <maxVel>1.0</maxVel>
    <minDepth>0.001</minDepth>
  </gazebo>
  <joint name = "palm_right_finger" type = "revolute">
    <parent link = "mani_forearm"/>
    <child link = "mani_right_finger"/>
    <origin xyz = "0.33 -0.0125 -0.006"/>
    <axis xyz = "0 0 1"/>
    <limit effort = "1000.0" lower="-1.57" upper="1.57" velocity="0.5"/>
    <mimic joint = "palm_left_finger" multiplier = "-1" offset = "0"/>
    <dynamics damping="0.1" friction="0.0"/>
  </joint>

  <!-- right fingertip -->
   <link name = "mani_right_finger_tip">
     <visual>
        <geometry>
            <box size="0.07 0.006  0.025"/>
        </geometry>
        <origin rpy = "0 0 0" xyz = "0.035 0 0"/>
    </visual>
    <collision>
      <origin xyz="0.035 0 0" rpy="0 0 0"/>
      <geometry>
        <box size="0.07 0.006  0.025"/>
      </geometry>
    </collision>
    <collision>
    <origin xyz="0.071 0.005 0" rpy="0 0 0" />
    <geometry>
      <box size="0.001 0.008  0.025"/>
    </geometry>
  </collision>
    <inertial>
      <mass value="0.1"/>
      <inertia ixx="0.001" ixy="0.0" ixz="0.001" iyy="0.0" iyz="0.0" izz="0.001"/>
    </inertial>
  </link>
  <gazebo reference="mani_right_finger_tip">
    <material>Gazebo/Grey</material>
    <kp>1000000.0</kp>
    <kd>100.0</kd>
    <mu1>30.0</mu1>
    <mu2>30.0</mu2>
    <maxVel>1.0</maxVel>
    <minDepth>0.001</minDepth>
  </gazebo>
  <joint name = "right_finger_tip" type = "revolute">
    <parent link = "mani_right_finger"/>
    <child link = "mani_right_finger_tip"/>
      <origin xyz = "0.1 0 0"/>
    <axis xyz = "0 0 1"/>
    <limit effort = "1000.0" lower="-1.57" upper="1.57"  velocity="0.5"/>
    <mimic joint = "palm_left_finger" multiplier = "1" offset = "0"/>
    <dynamics damping="0.1" friction="0.0"/>
  </joint>
  <transmission name="right_finger_tip_transmission">
    <type>transmission_interface/SimpleTransmission</type>
    <joint name="right_finger_tip">
      <hardwareInterface>hardware_interface/PositionJointInterface</hardwareInterface>
    </joint>  
    <actuator name="right_finger_tip_motor">
      <hardwareInterface>PositionJointInterface</hardwareInterface>
      <mechanicalReduction>1</mechanicalReduction>
    </actuator>
  </transmission>

<!-- Lidar -->
<link name = "laser_link">
  <visual>
   <geometry>
      <cylinder length="0.001" radius="0.001"/>
   </geometry>
   <origin rpy = "0 0 0" xyz = "0 0 0"/>
  </visual>
</link>
<joint name="laser_joint" type="fixed">
    <origin rpy="0 0 0" xyz="0 0 0.15"  /> <!--pos-->
    <parent link="base_link" />
    <child link="laser_link" />
</joint>

<!-- Gazebo plugin for RpLidar A2 -->
<gazebo reference="laser_link">
  <sensor type="ray" name="laser_link">
    <pose>0 0 0.06 0 0 0</pose>
    <visualize>false</visualize>
    <update_rate>10</update_rate>
    <ray>
      <scan>
        <horizontal>
          <samples>360</samples>
          <resolution>1</resolution>
          <min_angle>-3.14159265</min_angle>
          <max_angle>3.14159265</max_angle>
        </horizontal>
      </scan>
      <range>
        <min>0.24</min>
        <max>10.0</max>
        <resolution>0.01</resolution>
      </range>
      <noise>
        <type>gaussian</type>
        <mean>0.0</mean>
        <stddev>0.01</stddev>
      </noise>
    </ray>
    <plugin name="gazebo_ros_laser_link_controller" filename="libgazebo_ros_ray_sensor.so">
      <ros>
        <namespace>/</namespace>
        <remapping>~/out:=scan</remapping>
      </ros>
      <output_type>sensor_msgs/LaserScan</output_type>
      <frame_name>laser_link</frame_name>
    </plugin>
  </sensor>
</gazebo>

<!-- Kinect -->
<link name = "kinect2_dock">
  <visual>
   <geometry>
    <!-- <box size=".01 .25 .07"/>-->
    <box size="0.001 0.001 0.001"/>
   </geometry>
   <origin rpy = "0 0 0" xyz = "0 0 0"/>
  </visual>
</link>
<joint name="kinect_height" type="fixed">
  <parent link="base_link"/>
  <child link="kinect2_dock"/>
  <origin xyz="0.145 -0.013 1.37" rpy="0 0 0"/> 
</joint>

<link name = "kinect2_head_frame">
  <visual>
   <geometry>
    <box size="0.001 0.001 0.001"/>
   </geometry>
   <origin xyz = "0 0 0" rpy = "0 0 0"/>
  </visual>
</link>
<!--kinect_pitch -->
<joint name="kinect_pitch" type="fixed">
  <origin xyz="0 0 0" rpy="0 0.5 0" /> 
  <parent link="kinect2_dock" />
  <child link="kinect2_head_frame" />
</joint>

<link name = "kinect2_front_frame">
  <visual>
   <geometry>
    <box size="0.001 0.001 0.001"/>
   </geometry>
   <origin xyz = "0 0 0" rpy = "0 0 0"/>
  </visual>
</link>
<joint name="kinect_head" type="fixed">
  <origin xyz="0 0 0" rpy=" 0 1.57 0" /> 
  <parent link="kinect2_head_frame" />
  <child link="kinect2_front_frame" />
</joint>
<link name = "kinect2_ir_optical_frame">
  <visual>
   <geometry>
    <!-- <box size=".25 .04 .07"/>-->
    <box size="0.001 0.001 0.001"/>
   </geometry>
   <origin xyz = "0 0 0" rpy = "0 0 0"/>
  </visual>
</link>
<joint name="kinect_ir_trans" type="fixed">
  <origin xyz="0 0 0" rpy="0 0 -1.57" /> 
  <parent link="kinect2_front_frame" />
  <child link="kinect2_ir_optical_frame" />
</joint>

<link name = "kinect2_camera_frame">
  <visual>
   <geometry>
    <box size="0.001 0.001 0.001"/>
   </geometry>
   <origin rpy = "0 0 0" xyz = "0 0 0" />
  </visual>
</link>
<joint name="kinect_camra_joint" type="fixed">
    <origin xyz="0 0 0" rpy="3.1415926 0 -1.5707963" />
    <parent link="kinect2_ir_optical_frame" />
    <child link="kinect2_camera_frame" />
</joint>

<link name = "kinect2_rgb_optical_frame">
  <visual>
   <geometry>
    <box size="0.001 0.001 0.001"/>
   </geometry>
   <origin rpy = "0 0 0" xyz = "0 0 0" />
  </visual>
</link>
<joint name="kinect_hd_joint" type="fixed">
    <origin xyz="0 0 0" rpy="0 1.5707963 0" />
    <parent link="kinect2_camera_frame" />
    <child link="kinect2_rgb_optical_frame" />
</joint>

<!-- Gazebo plugin for Kinect v2 -->
<gazebo reference="kinect2_head_frame">
  <sensor type="depth" name="kinect2_depth_sensor" >
    <always_on>true</always_on>
    <update_rate>10.0</update_rate>
    <camera name="kinect2_depth_sensor">
      <horizontal_fov>1.221730456</horizontal_fov>
      <image>
          <width>512</width>
          <height>424</height>
          <format>B8G8R8</format>
      </image>
      <clip>
          <near>0.5</near>
          <far>6.0</far>
      </clip>
      <noise>
          <type>gaussian</type>
          <mean>0.1</mean>
          <stddev>0.07</stddev>
      </noise>
    </camera>
    <plugin name="kinect2_depth_control" filename="libgazebo_ros_camera.so">
        <ros>
          <namespace>kinect2</namespace>
          <remapping>custom_camera/image_raw:=image_color_rect</remapping>
          <remapping>custom_camera/image_depth:=image_depth_rect</remapping>
          <remapping>custom_camera/camera_info:=camera_info</remapping>
          <remapping>custom_camera/camera_info_depth:=/depth_camera_info</remapping>
          <remapping>custom_camera/points:=points</remapping>
        </ros>
        <camera_name>sd</camera_name>
        <frame_name>kinect2_ir_optical_frame</frame_name>
        <hack_baseline>0.1</hack_baseline>
        <min_depth>0.001</min_depth>
        <max_depth>300.0</max_depth>
    </plugin>
  </sensor>
</gazebo>
<gazebo reference="kinect2_rgb_optical_frame">
    <sensor type="camera" name="kinect2_rgb_sensor">
        <always_on>true</always_on>
        <update_rate>20.0</update_rate>
        <camera name="hd">
          <horizontal_fov>1.221730456</horizontal_fov>
          <image>
              <width>1920</width>
              <height>1080</height>
              <format>B8G8R8</format>
          </image>
          <clip>
              <near>0.2</near>
              <far>10.0</far>
          </clip>
          <noise>
              <type>gaussian</type>
              <mean>0.0</mean>
              <stddev>0.007</stddev>
          </noise>
        </camera>
        <plugin name="kinect2_rgb_controller" filename="libgazebo_ros_camera.so">
          <ros>
            <namespace>kinect2</namespace>
            <remapping>image_raw:=image_color_rect</remapping>
            <remapping>camera_info:=camera_info</remapping>
          </ros>
          <camera_name>hd</camera_name>
          <frame_name>kinect2_rgb_optical_frame</frame_name>

          <hack_baseline>0.1</hack_baseline>
        </plugin>
    </sensor>
</gazebo>

<gazebo reference="kinect2_head_frame">
    <sensor type="camera" name="kinect2_qhd_rgb_sensor">
        <always_on>true</always_on>
        <update_rate>20.0</update_rate>
        <camera name="qhd">
          <horizontal_fov>1.221730456</horizontal_fov>
          <image>
              <width>960</width>
              <height>540</height>
              <format>R8G8B8</format>
          </image>
          <clip>
              <near>0.2</near>
              <far>10.0</far>
          </clip>
        </camera>
        <plugin name="kinect2_qhd_rgb_controller" filename="libgazebo_ros_camera.so">
          <ros>
            <namespace>kinect2</namespace>
            <remapping>image_raw:=image_color_rect</remapping>
            <remapping>camera_info:=camera_info</remapping>
          </ros>
          <camera_name>qhd</camera_name>
          <frame_name>kinect2_head_frame</frame_name>

          <hack_baseline>0.1</hack_baseline>
        </plugin>
    </sensor>
</gazebo>

<!-- Gazebo plugin for mobile base -->
<gazebo>
  <plugin name="base_controller" filename="libgazebo_ros_planar_move.so">
    <ros>
      <!-- <namespace>/wpb</namespace> -->
      <remapping>cmd_vel:=cmd_vel</remapping>
      <remapping>odom:=odom</remapping>
    </ros>
    <!-- Set control loop update rate -->
    <update_rate>100</update_rate>
    <!-- Set odom publish rate -->
    <publish_rate>20</publish_rate>
    <!-- Set if odom required -->
    <publish_odom>true</publish_odom>
    <publish_odom_tf>true</publish_odom_tf>
    <!-- Frame IDs -->
    <odometry_frame>odom</odometry_frame>
    <robot_base_frame>base_footprint</robot_base_frame>
    <!-- Set odom covariance -->
    <covariance_x>0.0001</covariance_x>
    <covariance_y>0.0001</covariance_y>
    <covariance_yaw>0.01</covariance_yaw>
  </plugin>
</gazebo> 

<!-- Gazebo plugin for IMU -->
<!-- <gazebo reference="body_link">
  <gravity>true</gravity>
  <sensor name="imu_sensor" type="imu">
    <always_on>true</always_on>
    <update_rate>100</update_rate>
    <imu>
      <angular_velocity>
        <x>
          <noise type="gaussian">
            <mean>0.0</mean>
            <stddev>2e-4</stddev>
          </noise>
        </x>
        <y>
          <noise type="gaussian">
            <mean>0.0</mean>
            <stddev>2e-4</stddev>
          </noise>
        </y>
        <z>
          <noise type="gaussian">
            <mean>0.0</mean>
            <stddev>2e-4</stddev>
          </noise>
        </z>
      </angular_velocity>
      <linear_acceleration>
        <x>
          <noise type="gaussian">
            <mean>0.0</mean>
            <stddev>1.7e-2</stddev>
          </noise>
        </x>
        <y>
          <noise type="gaussian">
            <mean>0.0</mean>
            <stddev>1.7e-2</stddev>
          </noise>
        </y>
        <z>
          <noise type="gaussian">
            <mean>0.0</mean>
            <stddev>1.7e-2</stddev>
          </noise>
        </z>
      </linear_acceleration>
    </imu>
    <plugin name="wpb_imu" filename="libgazebo_ros_imu_sensor.so">
      <ros>
        <namespace>/</namespace>
        <remapping>~/out:=imu</remapping>
      </ros>
      <frame_name>body_link</frame_name>
    </plugin>
  </sensor>
</gazebo> -->

  <!-- ros2_control plugin -->
  <ros2_control name="GazeboSimSystem" type="system">
    <hardware>
      <plugin>gazebo_ros2_control/GazeboSystem</plugin>
    </hardware>
    <joint name="mani_base">
        <command_interface name="position">
            <param name="min">0</param>
            <param name="max">0.7</param>
        </command_interface>
        <state_interface name="position" >
          <param name="initial_value">0.0</param>
        </state_interface>
    </joint>
    <joint name="elbow_forearm">
        <command_interface name="position">
            <param name="min">-3.1416</param>
            <param name="max">3.1416</param>
        </command_interface>
        <state_interface name="position" >
          <param name="initial_value">0.0</param>
        </state_interface>
    </joint>
    <joint name="palm_left_finger">
        <command_interface name="position">
            <param name="min">-3.1416</param>
            <param name="max">3.1416</param>
        </command_interface>
        <state_interface name="position" >
          <param name="initial_value">0.0</param>
        </state_interface>
    </joint>
    <joint name="left_finger_tip">
        <command_interface name="position">
            <param name="min">-3.1416</param>
            <param name="max">3.1416</param>
        </command_interface>
        <state_interface name="position" >
          <param name="initial_value">0.0</param>
        </state_interface>
    </joint>
    <joint name="palm_right_finger">
        <command_interface name="position">
            <param name="min">-3.1416</param>
            <param name="max">3.1416</param>
        </command_interface>
        <state_interface name="position" >
          <param name="initial_value">0.0</param>
        </state_interface>
    </joint>
    <joint name="right_finger_tip">
        <command_interface name="position">
            <param name="min">-3.1416</param>
            <param name="max">3.1416</param>
        </command_interface>
        <state_interface name="position" >
          <param name="initial_value">0.0</param>
        </state_interface>
    </joint>
  </ros2_control>

  <gazebo>
    <plugin name="gazebo_ros2_control" filename="libgazebo_ros2_control.so">
      <parameters>$(find wpr_simulation2)/config/wpb_home_controller.yaml</parameters>
    </plugin>
  </gazebo>

  <gazebo>
   <plugin name="gazebo_grasp_fix" filename="libgazebo_grasp_fix.so">
        <arm>
           <arm_name>wpb_home_arm</arm_name>
           <palm_link> elbow_forearm  </palm_link>
           <gripper_link> elbow_forearm </gripper_link>
           <gripper_link> palm_left_finger </gripper_link>
           <gripper_link> left_finger_tip </gripper_link>
           <gripper_link> palm_right_finger </gripper_link>
           <gripper_link> right_finger_tip </gripper_link>
        </arm>
       <forces_angle_tolerance>150</forces_angle_tolerance>
       <update_rate>4</update_rate>
       <grip_count_threshold>4</grip_count_threshold>
       <max_grip_count>8</max_grip_count>
       <release_tolerance>0.005</release_tolerance>
       <disable_collisions_on_attach>true</disable_collisions_on_attach>
       <contact_topic>__default_topic__</contact_topic>
    </plugin>
</gazebo>
  
</robot>
